Here is the list of inputs:
OPTIONS jobs 2
OPTIONS queues 3
OPTIONS allotments for queue  2 is   1
OPTIONS quantum length for queue  2 is  10
OPTIONS allotments for queue  1 is   1
OPTIONS quantum length for queue  1 is  20
OPTIONS allotments for queue  0 is   1
OPTIONS quantum length for queue  0 is  40
OPTIONS boost 0
OPTIONS ioTime 5
OPTIONS stayAfterIO False
OPTIONS iobump False


For each job, three defining characteristics are given:
  startTime : at what time does the job enter the system
  runTime   : the total CPU time needed by the job to finish
  ioFreq    : every ioFreq time units, the job issues an I/O
              (the I/O takes ioTime units to complete)

Job List:
  Job  0: startTime   0 - runTime 150 - ioFreq  10
  Job  1: startTime   0 - runTime 150 - ioFreq  10


Execution Trace:

[ time 0 ] JOB BEGINS by JOB 0
[ time 0 ] JOB BEGINS by JOB 1
[ time 0 ] Run JOB 0 at PRIORITY 2 [ TICKS 9 ALLOT 1 TIME 149 (of 150) ]
[ time 1 ] Run JOB 0 at PRIORITY 2 [ TICKS 8 ALLOT 1 TIME 148 (of 150) ]
[ time 2 ] Run JOB 0 at PRIORITY 2 [ TICKS 7 ALLOT 1 TIME 147 (of 150) ]
[ time 3 ] Run JOB 0 at PRIORITY 2 [ TICKS 6 ALLOT 1 TIME 146 (of 150) ]
[ time 4 ] Run JOB 0 at PRIORITY 2 [ TICKS 5 ALLOT 1 TIME 145 (of 150) ]
[ time 5 ] Run JOB 0 at PRIORITY 2 [ TICKS 4 ALLOT 1 TIME 144 (of 150) ]
[ time 6 ] Run JOB 0 at PRIORITY 2 [ TICKS 3 ALLOT 1 TIME 143 (of 150) ]
[ time 7 ] Run JOB 0 at PRIORITY 2 [ TICKS 2 ALLOT 1 TIME 142 (of 150) ]
[ time 8 ] Run JOB 0 at PRIORITY 2 [ TICKS 1 ALLOT 1 TIME 141 (of 150) ]
[ time 9 ] Run JOB 0 at PRIORITY 2 [ TICKS 0 ALLOT 1 TIME 140 (of 150) ]
[ time 10 ] IO_START by JOB 0
IO DONE
[ time 10 ] Run JOB 1 at PRIORITY 2 [ TICKS 9 ALLOT 1 TIME 149 (of 150) ]
[ time 11 ] Run JOB 1 at PRIORITY 2 [ TICKS 8 ALLOT 1 TIME 148 (of 150) ]
[ time 12 ] Run JOB 1 at PRIORITY 2 [ TICKS 7 ALLOT 1 TIME 147 (of 150) ]
[ time 13 ] Run JOB 1 at PRIORITY 2 [ TICKS 6 ALLOT 1 TIME 146 (of 150) ]
[ time 14 ] Run JOB 1 at PRIORITY 2 [ TICKS 5 ALLOT 1 TIME 145 (of 150) ]
[ time 15 ] IO_DONE by JOB 0
[ time 15 ] Run JOB 1 at PRIORITY 2 [ TICKS 4 ALLOT 1 TIME 144 (of 150) ]
[ time 16 ] Run JOB 1 at PRIORITY 2 [ TICKS 3 ALLOT 1 TIME 143 (of 150) ]
[ time 17 ] Run JOB 1 at PRIORITY 2 [ TICKS 2 ALLOT 1 TIME 142 (of 150) ]
[ time 18 ] Run JOB 1 at PRIORITY 2 [ TICKS 1 ALLOT 1 TIME 141 (of 150) ]
[ time 19 ] Run JOB 1 at PRIORITY 2 [ TICKS 0 ALLOT 1 TIME 140 (of 150) ]
[ time 20 ] IO_START by JOB 1
IO DONE
[ time 20 ] Run JOB 0 at PRIORITY 1 [ TICKS 19 ALLOT 1 TIME 139 (of 150) ]
[ time 21 ] Run JOB 0 at PRIORITY 1 [ TICKS 18 ALLOT 1 TIME 138 (of 150) ]
[ time 22 ] Run JOB 0 at PRIORITY 1 [ TICKS 17 ALLOT 1 TIME 137 (of 150) ]
[ time 23 ] Run JOB 0 at PRIORITY 1 [ TICKS 16 ALLOT 1 TIME 136 (of 150) ]
[ time 24 ] Run JOB 0 at PRIORITY 1 [ TICKS 15 ALLOT 1 TIME 135 (of 150) ]
[ time 25 ] IO_DONE by JOB 1
[ time 25 ] Run JOB 0 at PRIORITY 1 [ TICKS 14 ALLOT 1 TIME 134 (of 150) ]
[ time 26 ] Run JOB 0 at PRIORITY 1 [ TICKS 13 ALLOT 1 TIME 133 (of 150) ]
[ time 27 ] Run JOB 0 at PRIORITY 1 [ TICKS 12 ALLOT 1 TIME 132 (of 150) ]
[ time 28 ] Run JOB 0 at PRIORITY 1 [ TICKS 11 ALLOT 1 TIME 131 (of 150) ]
[ time 29 ] Run JOB 0 at PRIORITY 1 [ TICKS 10 ALLOT 1 TIME 130 (of 150) ]
[ time 30 ] IO_START by JOB 0
IO DONE
[ time 30 ] Run JOB 1 at PRIORITY 1 [ TICKS 19 ALLOT 1 TIME 139 (of 150) ]
[ time 31 ] Run JOB 1 at PRIORITY 1 [ TICKS 18 ALLOT 1 TIME 138 (of 150) ]
[ time 32 ] Run JOB 1 at PRIORITY 1 [ TICKS 17 ALLOT 1 TIME 137 (of 150) ]
[ time 33 ] Run JOB 1 at PRIORITY 1 [ TICKS 16 ALLOT 1 TIME 136 (of 150) ]
[ time 34 ] Run JOB 1 at PRIORITY 1 [ TICKS 15 ALLOT 1 TIME 135 (of 150) ]
[ time 35 ] IO_DONE by JOB 0
[ time 35 ] Run JOB 1 at PRIORITY 1 [ TICKS 14 ALLOT 1 TIME 134 (of 150) ]
[ time 36 ] Run JOB 1 at PRIORITY 1 [ TICKS 13 ALLOT 1 TIME 133 (of 150) ]
[ time 37 ] Run JOB 1 at PRIORITY 1 [ TICKS 12 ALLOT 1 TIME 132 (of 150) ]
[ time 38 ] Run JOB 1 at PRIORITY 1 [ TICKS 11 ALLOT 1 TIME 131 (of 150) ]
[ time 39 ] Run JOB 1 at PRIORITY 1 [ TICKS 10 ALLOT 1 TIME 130 (of 150) ]
[ time 40 ] IO_START by JOB 1
IO DONE
[ time 40 ] Run JOB 0 at PRIORITY 1 [ TICKS 9 ALLOT 1 TIME 129 (of 150) ]
[ time 41 ] Run JOB 0 at PRIORITY 1 [ TICKS 8 ALLOT 1 TIME 128 (of 150) ]
[ time 42 ] Run JOB 0 at PRIORITY 1 [ TICKS 7 ALLOT 1 TIME 127 (of 150) ]
[ time 43 ] Run JOB 0 at PRIORITY 1 [ TICKS 6 ALLOT 1 TIME 126 (of 150) ]
[ time 44 ] Run JOB 0 at PRIORITY 1 [ TICKS 5 ALLOT 1 TIME 125 (of 150) ]
[ time 45 ] IO_DONE by JOB 1
[ time 45 ] Run JOB 0 at PRIORITY 1 [ TICKS 4 ALLOT 1 TIME 124 (of 150) ]
[ time 46 ] Run JOB 0 at PRIORITY 1 [ TICKS 3 ALLOT 1 TIME 123 (of 150) ]
[ time 47 ] Run JOB 0 at PRIORITY 1 [ TICKS 2 ALLOT 1 TIME 122 (of 150) ]
[ time 48 ] Run JOB 0 at PRIORITY 1 [ TICKS 1 ALLOT 1 TIME 121 (of 150) ]
[ time 49 ] Run JOB 0 at PRIORITY 1 [ TICKS 0 ALLOT 1 TIME 120 (of 150) ]
[ time 50 ] IO_START by JOB 0
IO DONE
[ time 50 ] Run JOB 1 at PRIORITY 1 [ TICKS 9 ALLOT 1 TIME 129 (of 150) ]
[ time 51 ] Run JOB 1 at PRIORITY 1 [ TICKS 8 ALLOT 1 TIME 128 (of 150) ]
[ time 52 ] Run JOB 1 at PRIORITY 1 [ TICKS 7 ALLOT 1 TIME 127 (of 150) ]
[ time 53 ] Run JOB 1 at PRIORITY 1 [ TICKS 6 ALLOT 1 TIME 126 (of 150) ]
[ time 54 ] Run JOB 1 at PRIORITY 1 [ TICKS 5 ALLOT 1 TIME 125 (of 150) ]
[ time 55 ] IO_DONE by JOB 0
[ time 55 ] Run JOB 1 at PRIORITY 1 [ TICKS 4 ALLOT 1 TIME 124 (of 150) ]
[ time 56 ] Run JOB 1 at PRIORITY 1 [ TICKS 3 ALLOT 1 TIME 123 (of 150) ]
[ time 57 ] Run JOB 1 at PRIORITY 1 [ TICKS 2 ALLOT 1 TIME 122 (of 150) ]
[ time 58 ] Run JOB 1 at PRIORITY 1 [ TICKS 1 ALLOT 1 TIME 121 (of 150) ]
[ time 59 ] Run JOB 1 at PRIORITY 1 [ TICKS 0 ALLOT 1 TIME 120 (of 150) ]
[ time 60 ] IO_START by JOB 1
IO DONE
[ time 60 ] Run JOB 0 at PRIORITY 0 [ TICKS 39 ALLOT 1 TIME 119 (of 150) ]
[ time 61 ] Run JOB 0 at PRIORITY 0 [ TICKS 38 ALLOT 1 TIME 118 (of 150) ]
[ time 62 ] Run JOB 0 at PRIORITY 0 [ TICKS 37 ALLOT 1 TIME 117 (of 150) ]
[ time 63 ] Run JOB 0 at PRIORITY 0 [ TICKS 36 ALLOT 1 TIME 116 (of 150) ]
[ time 64 ] Run JOB 0 at PRIORITY 0 [ TICKS 35 ALLOT 1 TIME 115 (of 150) ]
[ time 65 ] IO_DONE by JOB 1
[ time 65 ] Run JOB 0 at PRIORITY 0 [ TICKS 34 ALLOT 1 TIME 114 (of 150) ]
[ time 66 ] Run JOB 0 at PRIORITY 0 [ TICKS 33 ALLOT 1 TIME 113 (of 150) ]
[ time 67 ] Run JOB 0 at PRIORITY 0 [ TICKS 32 ALLOT 1 TIME 112 (of 150) ]
[ time 68 ] Run JOB 0 at PRIORITY 0 [ TICKS 31 ALLOT 1 TIME 111 (of 150) ]
[ time 69 ] Run JOB 0 at PRIORITY 0 [ TICKS 30 ALLOT 1 TIME 110 (of 150) ]
[ time 70 ] IO_START by JOB 0
IO DONE
[ time 70 ] Run JOB 1 at PRIORITY 0 [ TICKS 39 ALLOT 1 TIME 119 (of 150) ]
[ time 71 ] Run JOB 1 at PRIORITY 0 [ TICKS 38 ALLOT 1 TIME 118 (of 150) ]
[ time 72 ] Run JOB 1 at PRIORITY 0 [ TICKS 37 ALLOT 1 TIME 117 (of 150) ]
[ time 73 ] Run JOB 1 at PRIORITY 0 [ TICKS 36 ALLOT 1 TIME 116 (of 150) ]
[ time 74 ] Run JOB 1 at PRIORITY 0 [ TICKS 35 ALLOT 1 TIME 115 (of 150) ]
[ time 75 ] IO_DONE by JOB 0
[ time 75 ] Run JOB 1 at PRIORITY 0 [ TICKS 34 ALLOT 1 TIME 114 (of 150) ]
[ time 76 ] Run JOB 1 at PRIORITY 0 [ TICKS 33 ALLOT 1 TIME 113 (of 150) ]
[ time 77 ] Run JOB 1 at PRIORITY 0 [ TICKS 32 ALLOT 1 TIME 112 (of 150) ]
[ time 78 ] Run JOB 1 at PRIORITY 0 [ TICKS 31 ALLOT 1 TIME 111 (of 150) ]
[ time 79 ] Run JOB 1 at PRIORITY 0 [ TICKS 30 ALLOT 1 TIME 110 (of 150) ]
[ time 80 ] IO_START by JOB 1
IO DONE
[ time 80 ] Run JOB 0 at PRIORITY 0 [ TICKS 29 ALLOT 1 TIME 109 (of 150) ]
[ time 81 ] Run JOB 0 at PRIORITY 0 [ TICKS 28 ALLOT 1 TIME 108 (of 150) ]
[ time 82 ] Run JOB 0 at PRIORITY 0 [ TICKS 27 ALLOT 1 TIME 107 (of 150) ]
[ time 83 ] Run JOB 0 at PRIORITY 0 [ TICKS 26 ALLOT 1 TIME 106 (of 150) ]
[ time 84 ] Run JOB 0 at PRIORITY 0 [ TICKS 25 ALLOT 1 TIME 105 (of 150) ]
[ time 85 ] IO_DONE by JOB 1
[ time 85 ] Run JOB 0 at PRIORITY 0 [ TICKS 24 ALLOT 1 TIME 104 (of 150) ]
[ time 86 ] Run JOB 0 at PRIORITY 0 [ TICKS 23 ALLOT 1 TIME 103 (of 150) ]
[ time 87 ] Run JOB 0 at PRIORITY 0 [ TICKS 22 ALLOT 1 TIME 102 (of 150) ]
[ time 88 ] Run JOB 0 at PRIORITY 0 [ TICKS 21 ALLOT 1 TIME 101 (of 150) ]
[ time 89 ] Run JOB 0 at PRIORITY 0 [ TICKS 20 ALLOT 1 TIME 100 (of 150) ]
[ time 90 ] IO_START by JOB 0
IO DONE
[ time 90 ] Run JOB 1 at PRIORITY 0 [ TICKS 29 ALLOT 1 TIME 109 (of 150) ]
[ time 91 ] Run JOB 1 at PRIORITY 0 [ TICKS 28 ALLOT 1 TIME 108 (of 150) ]
[ time 92 ] Run JOB 1 at PRIORITY 0 [ TICKS 27 ALLOT 1 TIME 107 (of 150) ]
[ time 93 ] Run JOB 1 at PRIORITY 0 [ TICKS 26 ALLOT 1 TIME 106 (of 150) ]
[ time 94 ] Run JOB 1 at PRIORITY 0 [ TICKS 25 ALLOT 1 TIME 105 (of 150) ]
[ time 95 ] IO_DONE by JOB 0
[ time 95 ] Run JOB 1 at PRIORITY 0 [ TICKS 24 ALLOT 1 TIME 104 (of 150) ]
[ time 96 ] Run JOB 1 at PRIORITY 0 [ TICKS 23 ALLOT 1 TIME 103 (of 150) ]
[ time 97 ] Run JOB 1 at PRIORITY 0 [ TICKS 22 ALLOT 1 TIME 102 (of 150) ]
[ time 98 ] Run JOB 1 at PRIORITY 0 [ TICKS 21 ALLOT 1 TIME 101 (of 150) ]
[ time 99 ] Run JOB 1 at PRIORITY 0 [ TICKS 20 ALLOT 1 TIME 100 (of 150) ]
[ time 100 ] IO_START by JOB 1
IO DONE
[ time 100 ] Run JOB 0 at PRIORITY 0 [ TICKS 19 ALLOT 1 TIME 99 (of 150) ]
[ time 101 ] Run JOB 0 at PRIORITY 0 [ TICKS 18 ALLOT 1 TIME 98 (of 150) ]
[ time 102 ] Run JOB 0 at PRIORITY 0 [ TICKS 17 ALLOT 1 TIME 97 (of 150) ]
[ time 103 ] Run JOB 0 at PRIORITY 0 [ TICKS 16 ALLOT 1 TIME 96 (of 150) ]
[ time 104 ] Run JOB 0 at PRIORITY 0 [ TICKS 15 ALLOT 1 TIME 95 (of 150) ]
[ time 105 ] IO_DONE by JOB 1
[ time 105 ] Run JOB 0 at PRIORITY 0 [ TICKS 14 ALLOT 1 TIME 94 (of 150) ]
[ time 106 ] Run JOB 0 at PRIORITY 0 [ TICKS 13 ALLOT 1 TIME 93 (of 150) ]
[ time 107 ] Run JOB 0 at PRIORITY 0 [ TICKS 12 ALLOT 1 TIME 92 (of 150) ]
[ time 108 ] Run JOB 0 at PRIORITY 0 [ TICKS 11 ALLOT 1 TIME 91 (of 150) ]
[ time 109 ] Run JOB 0 at PRIORITY 0 [ TICKS 10 ALLOT 1 TIME 90 (of 150) ]
[ time 110 ] IO_START by JOB 0
IO DONE
[ time 110 ] Run JOB 1 at PRIORITY 0 [ TICKS 19 ALLOT 1 TIME 99 (of 150) ]
[ time 111 ] Run JOB 1 at PRIORITY 0 [ TICKS 18 ALLOT 1 TIME 98 (of 150) ]
[ time 112 ] Run JOB 1 at PRIORITY 0 [ TICKS 17 ALLOT 1 TIME 97 (of 150) ]
[ time 113 ] Run JOB 1 at PRIORITY 0 [ TICKS 16 ALLOT 1 TIME 96 (of 150) ]
[ time 114 ] Run JOB 1 at PRIORITY 0 [ TICKS 15 ALLOT 1 TIME 95 (of 150) ]
[ time 115 ] IO_DONE by JOB 0
[ time 115 ] Run JOB 1 at PRIORITY 0 [ TICKS 14 ALLOT 1 TIME 94 (of 150) ]
[ time 116 ] Run JOB 1 at PRIORITY 0 [ TICKS 13 ALLOT 1 TIME 93 (of 150) ]
[ time 117 ] Run JOB 1 at PRIORITY 0 [ TICKS 12 ALLOT 1 TIME 92 (of 150) ]
[ time 118 ] Run JOB 1 at PRIORITY 0 [ TICKS 11 ALLOT 1 TIME 91 (of 150) ]
[ time 119 ] Run JOB 1 at PRIORITY 0 [ TICKS 10 ALLOT 1 TIME 90 (of 150) ]
[ time 120 ] IO_START by JOB 1
IO DONE
[ time 120 ] Run JOB 0 at PRIORITY 0 [ TICKS 9 ALLOT 1 TIME 89 (of 150) ]
[ time 121 ] Run JOB 0 at PRIORITY 0 [ TICKS 8 ALLOT 1 TIME 88 (of 150) ]
[ time 122 ] Run JOB 0 at PRIORITY 0 [ TICKS 7 ALLOT 1 TIME 87 (of 150) ]
[ time 123 ] Run JOB 0 at PRIORITY 0 [ TICKS 6 ALLOT 1 TIME 86 (of 150) ]
[ time 124 ] Run JOB 0 at PRIORITY 0 [ TICKS 5 ALLOT 1 TIME 85 (of 150) ]
[ time 125 ] IO_DONE by JOB 1
[ time 125 ] Run JOB 0 at PRIORITY 0 [ TICKS 4 ALLOT 1 TIME 84 (of 150) ]
[ time 126 ] Run JOB 0 at PRIORITY 0 [ TICKS 3 ALLOT 1 TIME 83 (of 150) ]
[ time 127 ] Run JOB 0 at PRIORITY 0 [ TICKS 2 ALLOT 1 TIME 82 (of 150) ]
[ time 128 ] Run JOB 0 at PRIORITY 0 [ TICKS 1 ALLOT 1 TIME 81 (of 150) ]
[ time 129 ] Run JOB 0 at PRIORITY 0 [ TICKS 0 ALLOT 1 TIME 80 (of 150) ]
[ time 130 ] IO_START by JOB 0
IO DONE
[ time 130 ] Run JOB 1 at PRIORITY 0 [ TICKS 9 ALLOT 1 TIME 89 (of 150) ]
[ time 131 ] Run JOB 1 at PRIORITY 0 [ TICKS 8 ALLOT 1 TIME 88 (of 150) ]
[ time 132 ] Run JOB 1 at PRIORITY 0 [ TICKS 7 ALLOT 1 TIME 87 (of 150) ]
[ time 133 ] Run JOB 1 at PRIORITY 0 [ TICKS 6 ALLOT 1 TIME 86 (of 150) ]
[ time 134 ] Run JOB 1 at PRIORITY 0 [ TICKS 5 ALLOT 1 TIME 85 (of 150) ]
[ time 135 ] IO_DONE by JOB 0
[ time 135 ] Run JOB 1 at PRIORITY 0 [ TICKS 4 ALLOT 1 TIME 84 (of 150) ]
[ time 136 ] Run JOB 1 at PRIORITY 0 [ TICKS 3 ALLOT 1 TIME 83 (of 150) ]
[ time 137 ] Run JOB 1 at PRIORITY 0 [ TICKS 2 ALLOT 1 TIME 82 (of 150) ]
[ time 138 ] Run JOB 1 at PRIORITY 0 [ TICKS 1 ALLOT 1 TIME 81 (of 150) ]
[ time 139 ] Run JOB 1 at PRIORITY 0 [ TICKS 0 ALLOT 1 TIME 80 (of 150) ]
[ time 140 ] IO_START by JOB 1
IO DONE
[ time 140 ] Run JOB 0 at PRIORITY 0 [ TICKS 39 ALLOT 1 TIME 79 (of 150) ]
[ time 141 ] Run JOB 0 at PRIORITY 0 [ TICKS 38 ALLOT 1 TIME 78 (of 150) ]
[ time 142 ] Run JOB 0 at PRIORITY 0 [ TICKS 37 ALLOT 1 TIME 77 (of 150) ]
[ time 143 ] Run JOB 0 at PRIORITY 0 [ TICKS 36 ALLOT 1 TIME 76 (of 150) ]
[ time 144 ] Run JOB 0 at PRIORITY 0 [ TICKS 35 ALLOT 1 TIME 75 (of 150) ]
[ time 145 ] IO_DONE by JOB 1
[ time 145 ] Run JOB 0 at PRIORITY 0 [ TICKS 34 ALLOT 1 TIME 74 (of 150) ]
[ time 146 ] Run JOB 0 at PRIORITY 0 [ TICKS 33 ALLOT 1 TIME 73 (of 150) ]
[ time 147 ] Run JOB 0 at PRIORITY 0 [ TICKS 32 ALLOT 1 TIME 72 (of 150) ]
[ time 148 ] Run JOB 0 at PRIORITY 0 [ TICKS 31 ALLOT 1 TIME 71 (of 150) ]
[ time 149 ] Run JOB 0 at PRIORITY 0 [ TICKS 30 ALLOT 1 TIME 70 (of 150) ]
[ time 150 ] IO_START by JOB 0
IO DONE
[ time 150 ] Run JOB 1 at PRIORITY 0 [ TICKS 39 ALLOT 1 TIME 79 (of 150) ]
[ time 151 ] Run JOB 1 at PRIORITY 0 [ TICKS 38 ALLOT 1 TIME 78 (of 150) ]
[ time 152 ] Run JOB 1 at PRIORITY 0 [ TICKS 37 ALLOT 1 TIME 77 (of 150) ]
[ time 153 ] Run JOB 1 at PRIORITY 0 [ TICKS 36 ALLOT 1 TIME 76 (of 150) ]
[ time 154 ] Run JOB 1 at PRIORITY 0 [ TICKS 35 ALLOT 1 TIME 75 (of 150) ]
[ time 155 ] IO_DONE by JOB 0
[ time 155 ] Run JOB 1 at PRIORITY 0 [ TICKS 34 ALLOT 1 TIME 74 (of 150) ]
[ time 156 ] Run JOB 1 at PRIORITY 0 [ TICKS 33 ALLOT 1 TIME 73 (of 150) ]
[ time 157 ] Run JOB 1 at PRIORITY 0 [ TICKS 32 ALLOT 1 TIME 72 (of 150) ]
[ time 158 ] Run JOB 1 at PRIORITY 0 [ TICKS 31 ALLOT 1 TIME 71 (of 150) ]
[ time 159 ] Run JOB 1 at PRIORITY 0 [ TICKS 30 ALLOT 1 TIME 70 (of 150) ]
[ time 160 ] IO_START by JOB 1
IO DONE
[ time 160 ] Run JOB 0 at PRIORITY 0 [ TICKS 29 ALLOT 1 TIME 69 (of 150) ]
[ time 161 ] Run JOB 0 at PRIORITY 0 [ TICKS 28 ALLOT 1 TIME 68 (of 150) ]
[ time 162 ] Run JOB 0 at PRIORITY 0 [ TICKS 27 ALLOT 1 TIME 67 (of 150) ]
[ time 163 ] Run JOB 0 at PRIORITY 0 [ TICKS 26 ALLOT 1 TIME 66 (of 150) ]
[ time 164 ] Run JOB 0 at PRIORITY 0 [ TICKS 25 ALLOT 1 TIME 65 (of 150) ]
[ time 165 ] IO_DONE by JOB 1
[ time 165 ] Run JOB 0 at PRIORITY 0 [ TICKS 24 ALLOT 1 TIME 64 (of 150) ]
[ time 166 ] Run JOB 0 at PRIORITY 0 [ TICKS 23 ALLOT 1 TIME 63 (of 150) ]
[ time 167 ] Run JOB 0 at PRIORITY 0 [ TICKS 22 ALLOT 1 TIME 62 (of 150) ]
[ time 168 ] Run JOB 0 at PRIORITY 0 [ TICKS 21 ALLOT 1 TIME 61 (of 150) ]
[ time 169 ] Run JOB 0 at PRIORITY 0 [ TICKS 20 ALLOT 1 TIME 60 (of 150) ]
[ time 170 ] IO_START by JOB 0
IO DONE
[ time 170 ] Run JOB 1 at PRIORITY 0 [ TICKS 29 ALLOT 1 TIME 69 (of 150) ]
[ time 171 ] Run JOB 1 at PRIORITY 0 [ TICKS 28 ALLOT 1 TIME 68 (of 150) ]
[ time 172 ] Run JOB 1 at PRIORITY 0 [ TICKS 27 ALLOT 1 TIME 67 (of 150) ]
[ time 173 ] Run JOB 1 at PRIORITY 0 [ TICKS 26 ALLOT 1 TIME 66 (of 150) ]
[ time 174 ] Run JOB 1 at PRIORITY 0 [ TICKS 25 ALLOT 1 TIME 65 (of 150) ]
[ time 175 ] IO_DONE by JOB 0
[ time 175 ] Run JOB 1 at PRIORITY 0 [ TICKS 24 ALLOT 1 TIME 64 (of 150) ]
[ time 176 ] Run JOB 1 at PRIORITY 0 [ TICKS 23 ALLOT 1 TIME 63 (of 150) ]
[ time 177 ] Run JOB 1 at PRIORITY 0 [ TICKS 22 ALLOT 1 TIME 62 (of 150) ]
[ time 178 ] Run JOB 1 at PRIORITY 0 [ TICKS 21 ALLOT 1 TIME 61 (of 150) ]
[ time 179 ] Run JOB 1 at PRIORITY 0 [ TICKS 20 ALLOT 1 TIME 60 (of 150) ]
[ time 180 ] IO_START by JOB 1
IO DONE
[ time 180 ] Run JOB 0 at PRIORITY 0 [ TICKS 19 ALLOT 1 TIME 59 (of 150) ]
[ time 181 ] Run JOB 0 at PRIORITY 0 [ TICKS 18 ALLOT 1 TIME 58 (of 150) ]
[ time 182 ] Run JOB 0 at PRIORITY 0 [ TICKS 17 ALLOT 1 TIME 57 (of 150) ]
[ time 183 ] Run JOB 0 at PRIORITY 0 [ TICKS 16 ALLOT 1 TIME 56 (of 150) ]
[ time 184 ] Run JOB 0 at PRIORITY 0 [ TICKS 15 ALLOT 1 TIME 55 (of 150) ]
[ time 185 ] IO_DONE by JOB 1
[ time 185 ] Run JOB 0 at PRIORITY 0 [ TICKS 14 ALLOT 1 TIME 54 (of 150) ]
[ time 186 ] Run JOB 0 at PRIORITY 0 [ TICKS 13 ALLOT 1 TIME 53 (of 150) ]
[ time 187 ] Run JOB 0 at PRIORITY 0 [ TICKS 12 ALLOT 1 TIME 52 (of 150) ]
[ time 188 ] Run JOB 0 at PRIORITY 0 [ TICKS 11 ALLOT 1 TIME 51 (of 150) ]
[ time 189 ] Run JOB 0 at PRIORITY 0 [ TICKS 10 ALLOT 1 TIME 50 (of 150) ]
[ time 190 ] IO_START by JOB 0
IO DONE
[ time 190 ] Run JOB 1 at PRIORITY 0 [ TICKS 19 ALLOT 1 TIME 59 (of 150) ]
[ time 191 ] Run JOB 1 at PRIORITY 0 [ TICKS 18 ALLOT 1 TIME 58 (of 150) ]
[ time 192 ] Run JOB 1 at PRIORITY 0 [ TICKS 17 ALLOT 1 TIME 57 (of 150) ]
[ time 193 ] Run JOB 1 at PRIORITY 0 [ TICKS 16 ALLOT 1 TIME 56 (of 150) ]
[ time 194 ] Run JOB 1 at PRIORITY 0 [ TICKS 15 ALLOT 1 TIME 55 (of 150) ]
[ time 195 ] IO_DONE by JOB 0
[ time 195 ] Run JOB 1 at PRIORITY 0 [ TICKS 14 ALLOT 1 TIME 54 (of 150) ]
[ time 196 ] Run JOB 1 at PRIORITY 0 [ TICKS 13 ALLOT 1 TIME 53 (of 150) ]
[ time 197 ] Run JOB 1 at PRIORITY 0 [ TICKS 12 ALLOT 1 TIME 52 (of 150) ]
[ time 198 ] Run JOB 1 at PRIORITY 0 [ TICKS 11 ALLOT 1 TIME 51 (of 150) ]
[ time 199 ] Run JOB 1 at PRIORITY 0 [ TICKS 10 ALLOT 1 TIME 50 (of 150) ]
[ time 200 ] IO_START by JOB 1
IO DONE
[ time 200 ] Run JOB 0 at PRIORITY 0 [ TICKS 9 ALLOT 1 TIME 49 (of 150) ]
[ time 201 ] Run JOB 0 at PRIORITY 0 [ TICKS 8 ALLOT 1 TIME 48 (of 150) ]
[ time 202 ] Run JOB 0 at PRIORITY 0 [ TICKS 7 ALLOT 1 TIME 47 (of 150) ]
[ time 203 ] Run JOB 0 at PRIORITY 0 [ TICKS 6 ALLOT 1 TIME 46 (of 150) ]
[ time 204 ] Run JOB 0 at PRIORITY 0 [ TICKS 5 ALLOT 1 TIME 45 (of 150) ]
[ time 205 ] IO_DONE by JOB 1
[ time 205 ] Run JOB 0 at PRIORITY 0 [ TICKS 4 ALLOT 1 TIME 44 (of 150) ]
[ time 206 ] Run JOB 0 at PRIORITY 0 [ TICKS 3 ALLOT 1 TIME 43 (of 150) ]
[ time 207 ] Run JOB 0 at PRIORITY 0 [ TICKS 2 ALLOT 1 TIME 42 (of 150) ]
[ time 208 ] Run JOB 0 at PRIORITY 0 [ TICKS 1 ALLOT 1 TIME 41 (of 150) ]
[ time 209 ] Run JOB 0 at PRIORITY 0 [ TICKS 0 ALLOT 1 TIME 40 (of 150) ]
[ time 210 ] IO_START by JOB 0
IO DONE
[ time 210 ] Run JOB 1 at PRIORITY 0 [ TICKS 9 ALLOT 1 TIME 49 (of 150) ]
[ time 211 ] Run JOB 1 at PRIORITY 0 [ TICKS 8 ALLOT 1 TIME 48 (of 150) ]
[ time 212 ] Run JOB 1 at PRIORITY 0 [ TICKS 7 ALLOT 1 TIME 47 (of 150) ]
[ time 213 ] Run JOB 1 at PRIORITY 0 [ TICKS 6 ALLOT 1 TIME 46 (of 150) ]
[ time 214 ] Run JOB 1 at PRIORITY 0 [ TICKS 5 ALLOT 1 TIME 45 (of 150) ]
[ time 215 ] IO_DONE by JOB 0
[ time 215 ] Run JOB 1 at PRIORITY 0 [ TICKS 4 ALLOT 1 TIME 44 (of 150) ]
[ time 216 ] Run JOB 1 at PRIORITY 0 [ TICKS 3 ALLOT 1 TIME 43 (of 150) ]
[ time 217 ] Run JOB 1 at PRIORITY 0 [ TICKS 2 ALLOT 1 TIME 42 (of 150) ]
[ time 218 ] Run JOB 1 at PRIORITY 0 [ TICKS 1 ALLOT 1 TIME 41 (of 150) ]
[ time 219 ] Run JOB 1 at PRIORITY 0 [ TICKS 0 ALLOT 1 TIME 40 (of 150) ]
[ time 220 ] IO_START by JOB 1
IO DONE
[ time 220 ] Run JOB 0 at PRIORITY 0 [ TICKS 39 ALLOT 1 TIME 39 (of 150) ]
[ time 221 ] Run JOB 0 at PRIORITY 0 [ TICKS 38 ALLOT 1 TIME 38 (of 150) ]
[ time 222 ] Run JOB 0 at PRIORITY 0 [ TICKS 37 ALLOT 1 TIME 37 (of 150) ]
[ time 223 ] Run JOB 0 at PRIORITY 0 [ TICKS 36 ALLOT 1 TIME 36 (of 150) ]
[ time 224 ] Run JOB 0 at PRIORITY 0 [ TICKS 35 ALLOT 1 TIME 35 (of 150) ]
[ time 225 ] IO_DONE by JOB 1
[ time 225 ] Run JOB 0 at PRIORITY 0 [ TICKS 34 ALLOT 1 TIME 34 (of 150) ]
[ time 226 ] Run JOB 0 at PRIORITY 0 [ TICKS 33 ALLOT 1 TIME 33 (of 150) ]
[ time 227 ] Run JOB 0 at PRIORITY 0 [ TICKS 32 ALLOT 1 TIME 32 (of 150) ]
[ time 228 ] Run JOB 0 at PRIORITY 0 [ TICKS 31 ALLOT 1 TIME 31 (of 150) ]
[ time 229 ] Run JOB 0 at PRIORITY 0 [ TICKS 30 ALLOT 1 TIME 30 (of 150) ]
[ time 230 ] IO_START by JOB 0
IO DONE
[ time 230 ] Run JOB 1 at PRIORITY 0 [ TICKS 39 ALLOT 1 TIME 39 (of 150) ]
[ time 231 ] Run JOB 1 at PRIORITY 0 [ TICKS 38 ALLOT 1 TIME 38 (of 150) ]
[ time 232 ] Run JOB 1 at PRIORITY 0 [ TICKS 37 ALLOT 1 TIME 37 (of 150) ]
[ time 233 ] Run JOB 1 at PRIORITY 0 [ TICKS 36 ALLOT 1 TIME 36 (of 150) ]
[ time 234 ] Run JOB 1 at PRIORITY 0 [ TICKS 35 ALLOT 1 TIME 35 (of 150) ]
[ time 235 ] IO_DONE by JOB 0
[ time 235 ] Run JOB 1 at PRIORITY 0 [ TICKS 34 ALLOT 1 TIME 34 (of 150) ]
[ time 236 ] Run JOB 1 at PRIORITY 0 [ TICKS 33 ALLOT 1 TIME 33 (of 150) ]
[ time 237 ] Run JOB 1 at PRIORITY 0 [ TICKS 32 ALLOT 1 TIME 32 (of 150) ]
[ time 238 ] Run JOB 1 at PRIORITY 0 [ TICKS 31 ALLOT 1 TIME 31 (of 150) ]
[ time 239 ] Run JOB 1 at PRIORITY 0 [ TICKS 30 ALLOT 1 TIME 30 (of 150) ]
[ time 240 ] IO_START by JOB 1
IO DONE
[ time 240 ] Run JOB 0 at PRIORITY 0 [ TICKS 29 ALLOT 1 TIME 29 (of 150) ]
[ time 241 ] Run JOB 0 at PRIORITY 0 [ TICKS 28 ALLOT 1 TIME 28 (of 150) ]
[ time 242 ] Run JOB 0 at PRIORITY 0 [ TICKS 27 ALLOT 1 TIME 27 (of 150) ]
[ time 243 ] Run JOB 0 at PRIORITY 0 [ TICKS 26 ALLOT 1 TIME 26 (of 150) ]
[ time 244 ] Run JOB 0 at PRIORITY 0 [ TICKS 25 ALLOT 1 TIME 25 (of 150) ]
[ time 245 ] IO_DONE by JOB 1
[ time 245 ] Run JOB 0 at PRIORITY 0 [ TICKS 24 ALLOT 1 TIME 24 (of 150) ]
[ time 246 ] Run JOB 0 at PRIORITY 0 [ TICKS 23 ALLOT 1 TIME 23 (of 150) ]
[ time 247 ] Run JOB 0 at PRIORITY 0 [ TICKS 22 ALLOT 1 TIME 22 (of 150) ]
[ time 248 ] Run JOB 0 at PRIORITY 0 [ TICKS 21 ALLOT 1 TIME 21 (of 150) ]
[ time 249 ] Run JOB 0 at PRIORITY 0 [ TICKS 20 ALLOT 1 TIME 20 (of 150) ]
[ time 250 ] IO_START by JOB 0
IO DONE
[ time 250 ] Run JOB 1 at PRIORITY 0 [ TICKS 29 ALLOT 1 TIME 29 (of 150) ]
[ time 251 ] Run JOB 1 at PRIORITY 0 [ TICKS 28 ALLOT 1 TIME 28 (of 150) ]
[ time 252 ] Run JOB 1 at PRIORITY 0 [ TICKS 27 ALLOT 1 TIME 27 (of 150) ]
[ time 253 ] Run JOB 1 at PRIORITY 0 [ TICKS 26 ALLOT 1 TIME 26 (of 150) ]
[ time 254 ] Run JOB 1 at PRIORITY 0 [ TICKS 25 ALLOT 1 TIME 25 (of 150) ]
[ time 255 ] IO_DONE by JOB 0
[ time 255 ] Run JOB 1 at PRIORITY 0 [ TICKS 24 ALLOT 1 TIME 24 (of 150) ]
[ time 256 ] Run JOB 1 at PRIORITY 0 [ TICKS 23 ALLOT 1 TIME 23 (of 150) ]
[ time 257 ] Run JOB 1 at PRIORITY 0 [ TICKS 22 ALLOT 1 TIME 22 (of 150) ]
[ time 258 ] Run JOB 1 at PRIORITY 0 [ TICKS 21 ALLOT 1 TIME 21 (of 150) ]
[ time 259 ] Run JOB 1 at PRIORITY 0 [ TICKS 20 ALLOT 1 TIME 20 (of 150) ]
[ time 260 ] IO_START by JOB 1
IO DONE
[ time 260 ] Run JOB 0 at PRIORITY 0 [ TICKS 19 ALLOT 1 TIME 19 (of 150) ]
[ time 261 ] Run JOB 0 at PRIORITY 0 [ TICKS 18 ALLOT 1 TIME 18 (of 150) ]
[ time 262 ] Run JOB 0 at PRIORITY 0 [ TICKS 17 ALLOT 1 TIME 17 (of 150) ]
[ time 263 ] Run JOB 0 at PRIORITY 0 [ TICKS 16 ALLOT 1 TIME 16 (of 150) ]
[ time 264 ] Run JOB 0 at PRIORITY 0 [ TICKS 15 ALLOT 1 TIME 15 (of 150) ]
[ time 265 ] IO_DONE by JOB 1
[ time 265 ] Run JOB 0 at PRIORITY 0 [ TICKS 14 ALLOT 1 TIME 14 (of 150) ]
[ time 266 ] Run JOB 0 at PRIORITY 0 [ TICKS 13 ALLOT 1 TIME 13 (of 150) ]
[ time 267 ] Run JOB 0 at PRIORITY 0 [ TICKS 12 ALLOT 1 TIME 12 (of 150) ]
[ time 268 ] Run JOB 0 at PRIORITY 0 [ TICKS 11 ALLOT 1 TIME 11 (of 150) ]
[ time 269 ] Run JOB 0 at PRIORITY 0 [ TICKS 10 ALLOT 1 TIME 10 (of 150) ]
[ time 270 ] IO_START by JOB 0
IO DONE
[ time 270 ] Run JOB 1 at PRIORITY 0 [ TICKS 19 ALLOT 1 TIME 19 (of 150) ]
[ time 271 ] Run JOB 1 at PRIORITY 0 [ TICKS 18 ALLOT 1 TIME 18 (of 150) ]
[ time 272 ] Run JOB 1 at PRIORITY 0 [ TICKS 17 ALLOT 1 TIME 17 (of 150) ]
[ time 273 ] Run JOB 1 at PRIORITY 0 [ TICKS 16 ALLOT 1 TIME 16 (of 150) ]
[ time 274 ] Run JOB 1 at PRIORITY 0 [ TICKS 15 ALLOT 1 TIME 15 (of 150) ]
[ time 275 ] IO_DONE by JOB 0
[ time 275 ] Run JOB 1 at PRIORITY 0 [ TICKS 14 ALLOT 1 TIME 14 (of 150) ]
[ time 276 ] Run JOB 1 at PRIORITY 0 [ TICKS 13 ALLOT 1 TIME 13 (of 150) ]
[ time 277 ] Run JOB 1 at PRIORITY 0 [ TICKS 12 ALLOT 1 TIME 12 (of 150) ]
[ time 278 ] Run JOB 1 at PRIORITY 0 [ TICKS 11 ALLOT 1 TIME 11 (of 150) ]
[ time 279 ] Run JOB 1 at PRIORITY 0 [ TICKS 10 ALLOT 1 TIME 10 (of 150) ]
[ time 280 ] IO_START by JOB 1
IO DONE
[ time 280 ] Run JOB 0 at PRIORITY 0 [ TICKS 9 ALLOT 1 TIME 9 (of 150) ]
[ time 281 ] Run JOB 0 at PRIORITY 0 [ TICKS 8 ALLOT 1 TIME 8 (of 150) ]
[ time 282 ] Run JOB 0 at PRIORITY 0 [ TICKS 7 ALLOT 1 TIME 7 (of 150) ]
[ time 283 ] Run JOB 0 at PRIORITY 0 [ TICKS 6 ALLOT 1 TIME 6 (of 150) ]
[ time 284 ] Run JOB 0 at PRIORITY 0 [ TICKS 5 ALLOT 1 TIME 5 (of 150) ]
[ time 285 ] IO_DONE by JOB 1
[ time 285 ] Run JOB 0 at PRIORITY 0 [ TICKS 4 ALLOT 1 TIME 4 (of 150) ]
[ time 286 ] Run JOB 0 at PRIORITY 0 [ TICKS 3 ALLOT 1 TIME 3 (of 150) ]
[ time 287 ] Run JOB 0 at PRIORITY 0 [ TICKS 2 ALLOT 1 TIME 2 (of 150) ]
[ time 288 ] Run JOB 0 at PRIORITY 0 [ TICKS 1 ALLOT 1 TIME 1 (of 150) ]
[ time 289 ] Run JOB 0 at PRIORITY 0 [ TICKS 0 ALLOT 1 TIME 0 (of 150) ]
[ time 290 ] FINISHED JOB 0
[ time 290 ] Run JOB 1 at PRIORITY 0 [ TICKS 9 ALLOT 1 TIME 9 (of 150) ]
[ time 291 ] Run JOB 1 at PRIORITY 0 [ TICKS 8 ALLOT 1 TIME 8 (of 150) ]
[ time 292 ] Run JOB 1 at PRIORITY 0 [ TICKS 7 ALLOT 1 TIME 7 (of 150) ]
[ time 293 ] Run JOB 1 at PRIORITY 0 [ TICKS 6 ALLOT 1 TIME 6 (of 150) ]
[ time 294 ] Run JOB 1 at PRIORITY 0 [ TICKS 5 ALLOT 1 TIME 5 (of 150) ]
[ time 295 ] Run JOB 1 at PRIORITY 0 [ TICKS 4 ALLOT 1 TIME 4 (of 150) ]
[ time 296 ] Run JOB 1 at PRIORITY 0 [ TICKS 3 ALLOT 1 TIME 3 (of 150) ]
[ time 297 ] Run JOB 1 at PRIORITY 0 [ TICKS 2 ALLOT 1 TIME 2 (of 150) ]
[ time 298 ] Run JOB 1 at PRIORITY 0 [ TICKS 1 ALLOT 1 TIME 1 (of 150) ]
[ time 299 ] Run JOB 1 at PRIORITY 0 [ TICKS 0 ALLOT 1 TIME 0 (of 150) ]
[ time 300 ] FINISHED JOB 1

Final statistics:
Job  0: startTime   0 - response   0 - turnaround 290
Job  1: startTime   0 - response  10 - turnaround 300

  Avg  1: startTime n/a - response 5.00 - turnaround 295.00


[2, 2, 2, 2, 2, 2, 2, 2, 2, 2, 999, 999, 999, 999, 999, 999, 999, 999, 999, 999, 1, 1, 1, 1, 1, 1, 1, 1, 1, 1, 999, 999, 999, 999, 999, 999, 999, 999, 999, 999, 1, 1, 1, 1, 1, 1, 1, 1, 1, 1, 999, 999, 999, 999, 999, 999, 999, 999, 999, 999, 0, 0, 0, 0, 0, 0, 0, 0, 0, 0, 999, 999, 999, 999, 999, 999, 999, 999, 999, 999, 0, 0, 0, 0, 0, 0, 0, 0, 0, 0, 999, 999, 999, 999, 999, 999, 999, 999, 999, 999, 0, 0, 0, 0, 0, 0, 0, 0, 0, 0, 999, 999, 999, 999, 999, 999, 999, 999, 999, 999, 0, 0, 0, 0, 0, 0, 0, 0, 0, 0, 999, 999, 999, 999, 999, 999, 999, 999, 999, 999, 0, 0, 0, 0, 0, 0, 0, 0, 0, 0, 999, 999, 999, 999, 999, 999, 999, 999, 999, 999, 0, 0, 0, 0, 0, 0, 0, 0, 0, 0, 999, 999, 999, 999, 999, 999, 999, 999, 999, 999, 0, 0, 0, 0, 0, 0, 0, 0, 0, 0, 999, 999, 999, 999, 999, 999, 999, 999, 999, 999, 0, 0, 0, 0, 0, 0, 0, 0, 0, 0, 999, 999, 999, 999, 999, 999, 999, 999, 999, 999, 0, 0, 0, 0, 0, 0, 0, 0, 0, 0, 999, 999, 999, 999, 999, 999, 999, 999, 999, 999, 0, 0, 0, 0, 0, 0, 0, 0, 0, 0, 999, 999, 999, 999, 999, 999, 999, 999, 999, 999, 0, 0, 0, 0, 0, 0, 0, 0, 0, 0, 999, 999, 999, 999, 999, 999, 999, 999, 999, 999, 0, 0, 0, 0, 0, 0, 0, 0, 0, 0, 999, 999, 999, 999, 999, 999, 999, 999, 999, 999]
[999, 999, 999, 999, 999, 999, 999, 999, 999, 999, 2, 2, 2, 2, 2, 2, 2, 2, 2, 2, 999, 999, 999, 999, 999, 999, 999, 999, 999, 999, 1, 1, 1, 1, 1, 1, 1, 1, 1, 1, 999, 999, 999, 999, 999, 999, 999, 999, 999, 999, 1, 1, 1, 1, 1, 1, 1, 1, 1, 1, 999, 999, 999, 999, 999, 999, 999, 999, 999, 999, 0, 0, 0, 0, 0, 0, 0, 0, 0, 0, 999, 999, 999, 999, 999, 999, 999, 999, 999, 999, 0, 0, 0, 0, 0, 0, 0, 0, 0, 0, 999, 999, 999, 999, 999, 999, 999, 999, 999, 999, 0, 0, 0, 0, 0, 0, 0, 0, 0, 0, 999, 999, 999, 999, 999, 999, 999, 999, 999, 999, 0, 0, 0, 0, 0, 0, 0, 0, 0, 0, 999, 999, 999, 999, 999, 999, 999, 999, 999, 999, 0, 0, 0, 0, 0, 0, 0, 0, 0, 0, 999, 999, 999, 999, 999, 999, 999, 999, 999, 999, 0, 0, 0, 0, 0, 0, 0, 0, 0, 0, 999, 999, 999, 999, 999, 999, 999, 999, 999, 999, 0, 0, 0, 0, 0, 0, 0, 0, 0, 0, 999, 999, 999, 999, 999, 999, 999, 999, 999, 999, 0, 0, 0, 0, 0, 0, 0, 0, 0, 0, 999, 999, 999, 999, 999, 999, 999, 999, 999, 999, 0, 0, 0, 0, 0, 0, 0, 0, 0, 0, 999, 999, 999, 999, 999, 999, 999, 999, 999, 999, 0, 0, 0, 0, 0, 0, 0, 0, 0, 0, 999, 999, 999, 999, 999, 999, 999, 999, 999, 999, 0, 0, 0, 0, 0, 0, 0, 0, 0, 0, 999, 999, 999, 999, 999, 999, 999, 999, 999, 999, 0, 0, 0, 0, 0, 0, 0, 0, 0, 0]
[999, 999, 999, 999, 999, 999, 999, 999, 999, 999, 999, 999, 999, 999, 999, 999, 999, 999, 999, 999, 999, 999, 999, 999, 999, 999, 999, 999, 999, 999, 999, 999, 999, 999, 999, 999, 999, 999, 999, 999, 999, 999, 999, 999, 999, 999, 999, 999, 999, 999, 999, 999, 999, 999, 999, 999, 999, 999, 999, 999, 999, 999, 999, 999, 999, 999, 999, 999, 999, 999, 999, 999, 999, 999, 999, 999, 999, 999, 999, 999, 999, 999, 999, 999, 999, 999, 999, 999, 999, 999, 999, 999, 999, 999, 999, 999, 999, 999, 999, 999, 999, 999, 999, 999, 999, 999, 999, 999, 999, 999, 999, 999, 999, 999, 999, 999, 999, 999, 999, 999, 999, 999, 999, 999, 999, 999, 999, 999, 999, 999, 999, 999, 999, 999, 999, 999, 999, 999, 999, 999, 999, 999, 999, 999, 999, 999, 999, 999, 999, 999, 999, 999, 999, 999, 999, 999, 999, 999, 999, 999, 999, 999, 999, 999, 999, 999, 999, 999, 999, 999, 999, 999, 999, 999, 999, 999, 999, 999, 999, 999, 999, 999, 999, 999, 999, 999, 999, 999, 999, 999, 999, 999, 999, 999, 999, 999, 999, 999, 999, 999, 999, 999, 999, 999, 999, 999, 999, 999, 999, 999, 999, 999, 999, 999, 999, 999, 999, 999, 999, 999, 999, 999, 999, 999, 999, 999, 999, 999, 999, 999, 999, 999, 999, 999, 999, 999, 999, 999, 999, 999, 999, 999, 999, 999, 999, 999, 999, 999, 999, 999, 999, 999, 999, 999, 999, 999, 999, 999, 999, 999, 999, 999, 999, 999, 999, 999, 999, 999, 999, 999, 999, 999, 999, 999, 999, 999, 999, 999, 999, 999, 999, 999, 999, 999, 999, 999, 999, 999, 999, 999, 999, 999, 999, 999, 999, 999, 999, 999, 999, 999]
============================================================================================================================================================================================================================================================================================================
Q2
##########                                                                                                                                                                                                                                                                                                  
          $$$$$$$$$$                                                                                                                                                                                                                                                                                        
                                                                                                                                                                                                                                                                                                            
============================================================================================================================================================================================================================================================================================================
Q1
                    ##########          ##########                                                                                                                                                                                                                                                          
                              $$$$$$$$$$          $$$$$$$$$$                                                                                                                                                                                                                                                
                                                                                                                                                                                                                                                                                                            
============================================================================================================================================================================================================================================================================================================
Q0
                                                            ##########          ##########          ##########          ##########          ##########          ##########          ##########          ##########          ##########          ##########          ##########          ##########          
                                                                      $$$$$$$$$$          $$$$$$$$$$          $$$$$$$$$$          $$$$$$$$$$          $$$$$$$$$$          $$$$$$$$$$          $$$$$$$$$$          $$$$$$$$$$          $$$$$$$$$$          $$$$$$$$$$          $$$$$$$$$$          $$$$$$$$$$
                                                                                                                                                                                                                                                                                                            
============================================================================================================================================================================================================================================================================================================
0                                                 50                                                 100                                                 150                                                 200                                                 250                                                 300

