Here is the list of inputs:
OPTIONS jobs 1
OPTIONS queues 3
OPTIONS allotments for queue  2 is   1
OPTIONS quantum length for queue  2 is  10
OPTIONS allotments for queue  1 is   1
OPTIONS quantum length for queue  1 is  10
OPTIONS allotments for queue  0 is   1
OPTIONS quantum length for queue  0 is  10
OPTIONS boost 0
OPTIONS ioTime 5
OPTIONS stayAfterIO False
OPTIONS iobump False


For each job, three defining characteristics are given:
  startTime : at what time does the job enter the system
  runTime   : the total CPU time needed by the job to finish
  ioFreq    : every ioFreq time units, the job issues an I/O
              (the I/O takes ioTime units to complete)

Job List:
  Job  0: startTime   0 - runTime  84 - ioFreq   0


Execution Trace:

[ time 0 ] JOB BEGINS by JOB 0
[ time 0 ] Run JOB 0 at PRIORITY 2 [ TICKS 9 ALLOT 1 TIME 83 (of 84) ]
[ time 1 ] Run JOB 0 at PRIORITY 2 [ TICKS 8 ALLOT 1 TIME 82 (of 84) ]
[ time 2 ] Run JOB 0 at PRIORITY 2 [ TICKS 7 ALLOT 1 TIME 81 (of 84) ]
[ time 3 ] Run JOB 0 at PRIORITY 2 [ TICKS 6 ALLOT 1 TIME 80 (of 84) ]
[ time 4 ] Run JOB 0 at PRIORITY 2 [ TICKS 5 ALLOT 1 TIME 79 (of 84) ]
[ time 5 ] Run JOB 0 at PRIORITY 2 [ TICKS 4 ALLOT 1 TIME 78 (of 84) ]
[ time 6 ] Run JOB 0 at PRIORITY 2 [ TICKS 3 ALLOT 1 TIME 77 (of 84) ]
[ time 7 ] Run JOB 0 at PRIORITY 2 [ TICKS 2 ALLOT 1 TIME 76 (of 84) ]
[ time 8 ] Run JOB 0 at PRIORITY 2 [ TICKS 1 ALLOT 1 TIME 75 (of 84) ]
[ time 9 ] Run JOB 0 at PRIORITY 2 [ TICKS 0 ALLOT 1 TIME 74 (of 84) ]
[ time 10 ] Run JOB 0 at PRIORITY 1 [ TICKS 9 ALLOT 1 TIME 73 (of 84) ]
[ time 11 ] Run JOB 0 at PRIORITY 1 [ TICKS 8 ALLOT 1 TIME 72 (of 84) ]
[ time 12 ] Run JOB 0 at PRIORITY 1 [ TICKS 7 ALLOT 1 TIME 71 (of 84) ]
[ time 13 ] Run JOB 0 at PRIORITY 1 [ TICKS 6 ALLOT 1 TIME 70 (of 84) ]
[ time 14 ] Run JOB 0 at PRIORITY 1 [ TICKS 5 ALLOT 1 TIME 69 (of 84) ]
[ time 15 ] Run JOB 0 at PRIORITY 1 [ TICKS 4 ALLOT 1 TIME 68 (of 84) ]
[ time 16 ] Run JOB 0 at PRIORITY 1 [ TICKS 3 ALLOT 1 TIME 67 (of 84) ]
[ time 17 ] Run JOB 0 at PRIORITY 1 [ TICKS 2 ALLOT 1 TIME 66 (of 84) ]
[ time 18 ] Run JOB 0 at PRIORITY 1 [ TICKS 1 ALLOT 1 TIME 65 (of 84) ]
[ time 19 ] Run JOB 0 at PRIORITY 1 [ TICKS 0 ALLOT 1 TIME 64 (of 84) ]
[ time 20 ] Run JOB 0 at PRIORITY 0 [ TICKS 9 ALLOT 1 TIME 63 (of 84) ]
[ time 21 ] Run JOB 0 at PRIORITY 0 [ TICKS 8 ALLOT 1 TIME 62 (of 84) ]
[ time 22 ] Run JOB 0 at PRIORITY 0 [ TICKS 7 ALLOT 1 TIME 61 (of 84) ]
[ time 23 ] Run JOB 0 at PRIORITY 0 [ TICKS 6 ALLOT 1 TIME 60 (of 84) ]
[ time 24 ] Run JOB 0 at PRIORITY 0 [ TICKS 5 ALLOT 1 TIME 59 (of 84) ]
[ time 25 ] Run JOB 0 at PRIORITY 0 [ TICKS 4 ALLOT 1 TIME 58 (of 84) ]
[ time 26 ] Run JOB 0 at PRIORITY 0 [ TICKS 3 ALLOT 1 TIME 57 (of 84) ]
[ time 27 ] Run JOB 0 at PRIORITY 0 [ TICKS 2 ALLOT 1 TIME 56 (of 84) ]
[ time 28 ] Run JOB 0 at PRIORITY 0 [ TICKS 1 ALLOT 1 TIME 55 (of 84) ]
[ time 29 ] Run JOB 0 at PRIORITY 0 [ TICKS 0 ALLOT 1 TIME 54 (of 84) ]
[ time 30 ] Run JOB 0 at PRIORITY 0 [ TICKS 9 ALLOT 1 TIME 53 (of 84) ]
[ time 31 ] Run JOB 0 at PRIORITY 0 [ TICKS 8 ALLOT 1 TIME 52 (of 84) ]
[ time 32 ] Run JOB 0 at PRIORITY 0 [ TICKS 7 ALLOT 1 TIME 51 (of 84) ]
[ time 33 ] Run JOB 0 at PRIORITY 0 [ TICKS 6 ALLOT 1 TIME 50 (of 84) ]
[ time 34 ] Run JOB 0 at PRIORITY 0 [ TICKS 5 ALLOT 1 TIME 49 (of 84) ]
[ time 35 ] Run JOB 0 at PRIORITY 0 [ TICKS 4 ALLOT 1 TIME 48 (of 84) ]
[ time 36 ] Run JOB 0 at PRIORITY 0 [ TICKS 3 ALLOT 1 TIME 47 (of 84) ]
[ time 37 ] Run JOB 0 at PRIORITY 0 [ TICKS 2 ALLOT 1 TIME 46 (of 84) ]
[ time 38 ] Run JOB 0 at PRIORITY 0 [ TICKS 1 ALLOT 1 TIME 45 (of 84) ]
[ time 39 ] Run JOB 0 at PRIORITY 0 [ TICKS 0 ALLOT 1 TIME 44 (of 84) ]
[ time 40 ] Run JOB 0 at PRIORITY 0 [ TICKS 9 ALLOT 1 TIME 43 (of 84) ]
[ time 41 ] Run JOB 0 at PRIORITY 0 [ TICKS 8 ALLOT 1 TIME 42 (of 84) ]
[ time 42 ] Run JOB 0 at PRIORITY 0 [ TICKS 7 ALLOT 1 TIME 41 (of 84) ]
[ time 43 ] Run JOB 0 at PRIORITY 0 [ TICKS 6 ALLOT 1 TIME 40 (of 84) ]
[ time 44 ] Run JOB 0 at PRIORITY 0 [ TICKS 5 ALLOT 1 TIME 39 (of 84) ]
[ time 45 ] Run JOB 0 at PRIORITY 0 [ TICKS 4 ALLOT 1 TIME 38 (of 84) ]
[ time 46 ] Run JOB 0 at PRIORITY 0 [ TICKS 3 ALLOT 1 TIME 37 (of 84) ]
[ time 47 ] Run JOB 0 at PRIORITY 0 [ TICKS 2 ALLOT 1 TIME 36 (of 84) ]
[ time 48 ] Run JOB 0 at PRIORITY 0 [ TICKS 1 ALLOT 1 TIME 35 (of 84) ]
[ time 49 ] Run JOB 0 at PRIORITY 0 [ TICKS 0 ALLOT 1 TIME 34 (of 84) ]
[ time 50 ] Run JOB 0 at PRIORITY 0 [ TICKS 9 ALLOT 1 TIME 33 (of 84) ]
[ time 51 ] Run JOB 0 at PRIORITY 0 [ TICKS 8 ALLOT 1 TIME 32 (of 84) ]
[ time 52 ] Run JOB 0 at PRIORITY 0 [ TICKS 7 ALLOT 1 TIME 31 (of 84) ]
[ time 53 ] Run JOB 0 at PRIORITY 0 [ TICKS 6 ALLOT 1 TIME 30 (of 84) ]
[ time 54 ] Run JOB 0 at PRIORITY 0 [ TICKS 5 ALLOT 1 TIME 29 (of 84) ]
[ time 55 ] Run JOB 0 at PRIORITY 0 [ TICKS 4 ALLOT 1 TIME 28 (of 84) ]
[ time 56 ] Run JOB 0 at PRIORITY 0 [ TICKS 3 ALLOT 1 TIME 27 (of 84) ]
[ time 57 ] Run JOB 0 at PRIORITY 0 [ TICKS 2 ALLOT 1 TIME 26 (of 84) ]
[ time 58 ] Run JOB 0 at PRIORITY 0 [ TICKS 1 ALLOT 1 TIME 25 (of 84) ]
[ time 59 ] Run JOB 0 at PRIORITY 0 [ TICKS 0 ALLOT 1 TIME 24 (of 84) ]
[ time 60 ] Run JOB 0 at PRIORITY 0 [ TICKS 9 ALLOT 1 TIME 23 (of 84) ]
[ time 61 ] Run JOB 0 at PRIORITY 0 [ TICKS 8 ALLOT 1 TIME 22 (of 84) ]
[ time 62 ] Run JOB 0 at PRIORITY 0 [ TICKS 7 ALLOT 1 TIME 21 (of 84) ]
[ time 63 ] Run JOB 0 at PRIORITY 0 [ TICKS 6 ALLOT 1 TIME 20 (of 84) ]
[ time 64 ] Run JOB 0 at PRIORITY 0 [ TICKS 5 ALLOT 1 TIME 19 (of 84) ]
[ time 65 ] Run JOB 0 at PRIORITY 0 [ TICKS 4 ALLOT 1 TIME 18 (of 84) ]
[ time 66 ] Run JOB 0 at PRIORITY 0 [ TICKS 3 ALLOT 1 TIME 17 (of 84) ]
[ time 67 ] Run JOB 0 at PRIORITY 0 [ TICKS 2 ALLOT 1 TIME 16 (of 84) ]
[ time 68 ] Run JOB 0 at PRIORITY 0 [ TICKS 1 ALLOT 1 TIME 15 (of 84) ]
[ time 69 ] Run JOB 0 at PRIORITY 0 [ TICKS 0 ALLOT 1 TIME 14 (of 84) ]
[ time 70 ] Run JOB 0 at PRIORITY 0 [ TICKS 9 ALLOT 1 TIME 13 (of 84) ]
[ time 71 ] Run JOB 0 at PRIORITY 0 [ TICKS 8 ALLOT 1 TIME 12 (of 84) ]
[ time 72 ] Run JOB 0 at PRIORITY 0 [ TICKS 7 ALLOT 1 TIME 11 (of 84) ]
[ time 73 ] Run JOB 0 at PRIORITY 0 [ TICKS 6 ALLOT 1 TIME 10 (of 84) ]
[ time 74 ] Run JOB 0 at PRIORITY 0 [ TICKS 5 ALLOT 1 TIME 9 (of 84) ]
[ time 75 ] Run JOB 0 at PRIORITY 0 [ TICKS 4 ALLOT 1 TIME 8 (of 84) ]
[ time 76 ] Run JOB 0 at PRIORITY 0 [ TICKS 3 ALLOT 1 TIME 7 (of 84) ]
[ time 77 ] Run JOB 0 at PRIORITY 0 [ TICKS 2 ALLOT 1 TIME 6 (of 84) ]
[ time 78 ] Run JOB 0 at PRIORITY 0 [ TICKS 1 ALLOT 1 TIME 5 (of 84) ]
[ time 79 ] Run JOB 0 at PRIORITY 0 [ TICKS 0 ALLOT 1 TIME 4 (of 84) ]
[ time 80 ] Run JOB 0 at PRIORITY 0 [ TICKS 9 ALLOT 1 TIME 3 (of 84) ]
[ time 81 ] Run JOB 0 at PRIORITY 0 [ TICKS 8 ALLOT 1 TIME 2 (of 84) ]
[ time 82 ] Run JOB 0 at PRIORITY 0 [ TICKS 7 ALLOT 1 TIME 1 (of 84) ]
[ time 83 ] Run JOB 0 at PRIORITY 0 [ TICKS 6 ALLOT 1 TIME 0 (of 84) ]
[ time 84 ] FINISHED JOB 0

Final statistics:
Job  0: startTime   0 - response   0 - turnaround  84

  Avg  0: startTime n/a - response 0.00 - turnaround 84.00


====================================================================================
Q2
##########                                                                          
====================================================================================
Q1
          ##########                                                                
====================================================================================
Q0
                    ################################################################
====================================================================================
0                                                 50                                 84

